Workbook

Sheet Raw Data
B1: Cores/Agent | C1: Group | D1: Run | E1: Target | F1: Actions | G1: Total Cores | H1: UBAVisualizer (Session) Time | I1: VisualStudio Time | J1: Trace | M1: Cores/Agent | N1: Group | O1: Run | P1: Target | Q1: Actions | R1: Total Cores | S1: UBAVisualizer (Session) Time | T1: VisualStudio Time | U1: Trace | X1: Cores/Agent | Y1: Group | Z1: Run | AA1: Target | AB1: Actions | AC1: Total Cores | AD1: UBAVisualizer (Session) Time | AE1: VisualStudio Time | AF1: Trace
A2: Single Agent | B2: 32 | C2: 1 | D2: 1 | E2: UE5 | F2: 7914 | G2: 32 | H2: 31m 3s | I2: 31m 38s | J2: Group-1/Single-Agent-32-Core-UE5-Target-1.uba | L2: Single Agent | M2: 32 | N2: 1 | O2: 1 | P2: UnrealInsights | Q2: 501 | R2: 32 | S2: 2m 29s | T2: 2m 34s | U2: Group-1/Single-Agent-32-Core-UnrealInsights-Target-1.uba | W2: Single Agent | X2: 32 | Y2: 1 | Z2: 1 | AA2: UnrealPackageTool | AB2: 65 | AC2: 32 | AD2: 1m 17s | AE2: 1m 20s | AF2: Group-1/Single-Agent-32-Core-UnrealPackageTool-Target-1.uba
B3: 32 | C3: 2 | D3: 1 | E3: UE5 | F3: 7914 | G3: 32 | H3: 35m 47s | I3: 36m 39s | J3: Group-2/Single-Agent-32-Core-UE5-Target-1.uba | M3: 32 | N3: 2 | O3: 1 | P3: UnrealInsights | Q3: 501 | R3: 32 | S3: 2m 56s | T3: 3m 1s | U3: Group-2/Single-Agent-32-Core-UnrealInsights-Target-1.uba | X3: 32 | Y3: 2 | Z3: 1 | AA3: UnrealPackageTool | AB3: 65 | AC3: 32 | AD3: 1m 25s | AE3: 1m 29s | AF3: Group-2/Single-Agent-32-Core-UnrealPackageTool-Target-1.uba
B4: 32 | C4: 1 | D4: 2 | E4: UE5 | F4: 7914 | G4: 32 | H4: 29m 47s | I4: 30m 33s | J4: Group-1/Single-Agent-32-Core-UE5-Target-2.uba | M4: 32 | N4: 1 | O4: 2 | P4: UnrealInsights | Q4: 501 | R4: 32 | S4: 2m 25s | T4: 2m 31s | U4: Group-1/Single-Agent-32-Core-UnrealInsights-Target-2.uba | X4: 32 | Y4: 1 | Z4: 2 | AA4: UnrealPackageTool | AB4: 65 | AC4: 32 | AD4: 1m 24s | AE4: 1m 27s | AF4: Group-1/Single-Agent-32-Core-UnrealPackageTool-Target-2.uba
B5: 32 | C5: 2 | D5: 2 | E5: UE5 | F5: 7914 | G5: 32 | H5: 34m 26s | I5: 35m 13s | J5: Group-2/Single-Agent-32-Core-UE5-Target-2.uba | M5: 32 | N5: 2 | O5: 2 | P5: UnrealInsights | Q5: 501 | R5: 32 | S5: 2m 40s | T5: 2m 46s | U5: Group-2/Single-Agent-32-Core-UnrealInsights-Target-2.uba | X5: 32 | Y5: 2 | Z5: 2 | AA5: UnrealPackageTool | AB5: 65 | AC5: 32 | AD5: 1m 28s | AE5: 1m 31s | AF5: Group-2/Single-Agent-32-Core-UnrealPackageTool-Target-2.uba
B6: 16 | C6: 1 | D6: 1 | E6: UE5 | F6: 7914 | G6: 16 | H6: 50m 18s | I6: 51m 11s | J6: Group-1/Single-Agent-16-Core-UE5-Target-1.uba | M6: 16 | N6: 1 | O6: 1 | P6: UnrealInsights | Q6: 501 | R6: 16 | S6: 3m 17s | T6: 3m 25s | U6: Group-1/Single-Agent-16-Core-UnrealInsights-Target-1.uba | X6: 16 | Y6: 1 | Z6: 1 | AA6: UnrealPackageTool | AB6: 65 | AC6: 16 | AD6: 1m 38s | AE6: 1m 42s | AF6: Group-1/Single-Agent-16-Core-UnrealPackageTool-Target-1.uba
B7: 16 | C7: 2 | D7: 1 | E7: UE5 | F7: 7914 | G7: 16 | H7: 52m 0s | I7: 52m 51s | J7: Group-2/Single-Agent-16-Core-UE5-Target-1.uba | M7: 16 | N7: 2 | O7: 1 | P7: UnrealInsights | Q7: 501 | R7: 16 | S7: 3m 36s | T7: 3m 45s | U7: Group-2/Single-Agent-16-Core-UnrealInsights-Target-1.uba | X7: 16 | Y7: 2 | Z7: 1 | AA7: UnrealPackageTool | AB7: 65 | AC7: 16 | AD7: 1m 50s | AE7: 1m 54s | AF7: Group-2/Single-Agent-16-Core-UnrealPackageTool-Target-1.uba
B8: 16 | C8: 1 | D8: 2 | E8: UE5 | F8: 7914 | G8: 16 | H8: 50m 34s | I8: 56m 49s | J8: Group-1/Single-Agent-16-Core-UE5-Target-2.uba | M8: 16 | N8: 1 | O8: 2 | P8: UnrealInsights | Q8: 501 | R8: 16 | S8: 3m 9s | T8: 3m 15s | U8: Group-1/Single-Agent-16-Core-UnrealInsights-Target-2.uba | X8: 16 | Y8: 1 | Z8: 2 | AA8: UnrealPackageTool | AB8: 65 | AC8: 16 | AD8: 1m 28s | AE8: 1m 32s | AF8: Group-1/Single-Agent-16-Core-UnrealPackageTool-Target-2.uba
B9: 16 | C9: 2 | D9: 2 | E9: UE5 | F9: 7914 | G9: 16 | H9: 52m 13s | I9: 58m 5s | J9: Group-2/Single-Agent-16-Core-UE5-Target-2.uba | M9: 16 | N9: 2 | O9: 2 | P9: UnrealInsights | Q9: 501 | R9: 16 | S9: 3m 40s | T9: 3m 47s | U9: Group-2/Single-Agent-16-Core-UnrealInsights-Target-2.uba | X9: 16 | Y9: 2 | Z9: 2 | AA9: UnrealPackageTool | AB9: 65 | AC9: 16 | AD9: 1m 35s | AE9: 1m 39s | AF9: Group-2/Single-Agent-16-Core-UnrealPackageTool-Target-2.uba
B10: 64 | C10: 1 | D10: 1 | E10: UE5 | F10: 7914 | G10: 64 | H10: 25m 46s | I10: 31m 48s | J10: Group-1/Single-Agent-64-Core-UE5-Target-1.uba | M10: 64 | N10: 1 | O10: 1 | P10: UnrealInsights | Q10: 501 | R10: 64 | S10: 2m 13s | T10: 2m 50s | U10: Group-1/Single-Agent-64-Core-UnrealInsights-Target-1.uba | X10: 64 | Y10: 1 | Z10: 1 | AA10: UnrealPackageTool | AB10: 65 | AC10: 64 | AD10: 1m 27s | AE10: 1m 47s | AF10: Group-1/Single-Agent-64-Core-UnrealPackageTool-Target-1.uba
B11: 64 | C11: 2 | D11: 1 | E11: UE5 | F11: 7914 | G11: 64 | H11: 26m 56s | I11: 33m 38s | J11: Group-2/Single-Agent-64-Core-UE5-Target-1.uba | M11: 64 | N11: 2 | O11: 1 | P11: UnrealInsights | Q11: 501 | R11: 64 | S11: 2m 58s | T11: 3m 38s | U11: Group-2/Single-Agent-64-Core-UnrealInsights-Target-1.uba | X11: 64 | Y11: 2 | Z11: 1 | AA11: UnrealPackageTool | AB11: 65 | AC11: 64 | AD11: 1m 44s | AE11: 1m 49s | AF11: Group-2/Single-Agent-64-Core-UnrealPackageTool-Target-1.uba
B12: 64 | C12: 1 | D12: 2 | E12: UE5 | F12: 7914 | G12: 64 | H12: 26m 55s | I12: 33m 15s | J12: Group-1/Single-Agent-64-Core-UE5-Target-2.uba | M12: 64 | N12: 1 | O12: 2 | P12: UnrealInsights | Q12: 501 | R12: 64 | S12: 2m 1s | T12: 2m 7s | U12: Group-1/Single-Agent-64-Core-UnrealInsights-Target-2.uba | X12: 64 | Y12: 1 | Z12: 2 | AA12: UnrealPackageTool | AB12: 65 | AC12: 64 | AD12: 1m 17s | AE12: 1m 21s | AF12: Group-1/Single-Agent-64-Core-UnrealPackageTool-Target-2.uba
B13: 64 | C13: 2 | D13: 2 | E13: UE5 | F13: 7914 | G13: 64 | H13: 26m 42s | I13: 33m 11s | J13: Group-2/Single-Agent-64-Core-UE5-Target-2.uba | M13: 64 | N13: 2 | O13: 2 | P13: UnrealInsights | Q13: 501 | R13: 64 | S13: 1m 58s | T13: 2m 5s | U13: Group-2/Single-Agent-64-Core-UnrealInsights-Target-2.uba | X13: 64 | Y13: 2 | Z13: 2 | AA13: UnrealPackageTool | AB13: 65 | AC13: 64 | AD13: 1m 41s | AE13: 1m 45s | AF13: Group-2/Single-Agent-64-Core-UnrealPackageTool-Target-2.uba
B14: 8 | C14: 1 | D14: 1 | E14: UE5 | F14: 7914 | G14: 8 | H14: 1h 15m 50s | I14: 1h 22m 9s | J14: Group-1/Single-Agent-8-Core-UE5-Target-1.uba | M14: 8 | N14: 1 | O14: 1 | P14: UnrealInsights | Q14: 501 | R14: 8 | S14: 4m 8s | T14: 4m 13s | U14: Group-1/Single-Agent-8-Core-UnrealInsights-Target-1.uba | X14: 8 | Y14: 1 | Z14: 1 | AA14: UnrealPackageTool | AB14: 65 | AC14: 8 | AD14: 2m 1s | AE14: 2m 5s | AF14: Group-1/Single-Agent-8-Core-UnrealPackageTool-Target-1.uba
... B21: 4 | C21: 2 | D21: 2 | E21: UE5 | F21: 7914 | G21: 4 | H21: 1h 53m 58s | I21: 1h 54m 54s | J21: Group-2/Single-Agent-4-Core-UE5-Target-2.uba | M21: 4 | N21: 2 | O21: 2 | P21: UnrealInsights | Q21: 501 | R21: 4 | S21: 5m 36s | T21: 5m 43s | U21: Group-2/Single-Agent-4-Core-UnrealInsights-Target-2.uba | X21: 4 | Y21: 2 | Z21: 2 | AA21: UnrealPackageTool | AB21: 65 | AC21: 4 | AD21: 2m 19s | AE21: 2m 22s | AF21: Group-2/Single-Agent-4-Core-UnrealPackageTool-Target-2.uba
B22: Cores/Agent | C22: Group | D22: Run | E22: Target | F22: Actions | G22: Total Cores | H22: UBAVisualizer (Session) Time | I22: VisualStudio Time | J22: Trace | M22: Cores/Agent | N22: Group | O22: Run | P22: Target | Q22: Actions | R22: Total Cores | S22: UBAVisualizer (Session) Time | T22: VisualStudio Time | U22: Trace | X22: Cores/Agent | Y22: Group | Z22: Run | AA22: Target | AB22: Actions | AC22: Total Cores | AD22: UBAVisualizer (Session) Time | AE22: VisualStudio Time | AF22: Trace
A23: Quad Agent | B23: 4 | C23: 1 | D23: 1 | E23: UE5 | F23: 7914 | G23: 16 | H23: 54m 54s | I23: 1h 1m 7s | J23: Group-1/Quad-Agent-4-Core-UE5-Target-1.uba | L23: Quad Agent | M23: 4 | N23: 1 | O23: 1 | P23: UnrealInsights | Q23: 501 | R23: 16 | S23: 4m 3s | T23: 4m 8s | U23: Group-1/Quad-Agent-4-Core-UnrealInsights-Target-1.uba | W23: Quad Agent | X23: 4 | Y23: 1 | Z23: 1 | AA23: UnrealPackageTool | AB23: 65 | AC23: 16 | AD23: 1m 42s | AE23: 1m 46s | AF23: Group-1/Quad-Agent-4-Core-UnrealPackageTool-Target-1.uba
B24: 4 | C24: 2 | D24: 1 | E24: UE5 | F24: 7914 | G24: 16 | H24: 59m 22s | I24: 1h 5m 44s | J24: Group-2/Quad-Agent-4-Core-UE5-Target-1.uba | M24: 4 | N24: 2 | O24: 1 | P24: UnrealInsights | Q24: 501 | R24: 16 | S24: 3m 54s | T24: 3m 59s | U24: Group-2/Quad-Agent-4-Core-UnrealInsights-Target-1.uba | X24: 4 | Y24: 2 | Z24: 1 | AA24: UnrealPackageTool | AB24: 65 | AC24: 16 | AD24: 1m 44s | AE24: 1m 48s | AF24: Group-2/Quad-Agent-4-Core-UnrealPackageTool-Target-1.uba
B25: 4 | C25: 1 | D25: 2 | E25: UE5 | F25: 7914 | G25: 16 | H25: 54m 46s | I25: 1h 1m 0s | J25: Group-1/Quad-Agent-4-Core-UE5-Target-2.uba | M25: 4 | N25: 1 | O25: 2 | P25: UnrealInsights | Q25: 501 | R25: 16 | S25: 3m 51s | T25: 3m 56s | U25: Group-1/Quad-Agent-4-Core-UnrealInsights-Target-2.uba | X25: 4 | Y25: 1 | Z25: 2 | AA25: UnrealPackageTool | AB25: 65 | AC25: 16 | AD25: 1m 37s | AE25: 1m 40s | AF25: Group-1/Quad-Agent-4-Core-UnrealPackageTool-Target-2.uba
B26: 4 | C26: 2 | D26: 2 | E26: UE5 | F26: 7914 | G26: 16 | H26: 55m 31s | I26: 1h 1m 25s | J26: Group-2/Quad-Agent-4-Core-UE5-Target-2.uba | M26: 4 | N26: 2 | O26: 2 | P26: UnrealInsights | Q26: 501 | R26: 16 | S26: 3m 51s | T26: 3m 57s | U26: Group-2/Quad-Agent-4-Core-UnrealInsights-Target-2.uba | X26: 4 | Y26: 2 | Z26: 2 | AA26: UnrealPackageTool | AB26: 65 | AC26: 16 | AD26: 1m 41s | AE26: 1m 44s | AF26: Group-2/Quad-Agent-4-Core-UnrealPackageTool-Target-2.uba
B27: 8 | C27: 1 | D27: 1 | E27: UE5 | F27: 7914 | G27: 32 | H27: 38m 58s | I27: 45m 16s | J27: Group-1/Quad-Agent-8-Core-UE5-Target-1.uba | M27: 8 | N27: 1 | O27: 1 | P27: UnrealInsights | Q27: 501 | R27: 32 | S27: 3m 28s | T27: 3m 34s | U27: Group-1/Quad-Agent-8-Core-UnrealInsights-Target-1.uba | X27: 8 | Y27: 1 | Z27: 1 | AA27: UnrealPackageTool | AB27: 65 | AC27: 32 | AD27: 1m 22s | AE27: 1m 25s | AF27: Group-1/Quad-Agent-8-Core-UnrealPackageTool-Target-1.uba
B28: 8 | C28: 2 | D28: 1 | E28: UE5 | F28: 7914 | G28: 32 | H28: 39m 50s | I28: 46m 14s | J28: Group-2/Quad-Agent-8-Core-UE5-Target-1.uba | M28: 8 | N28: 2 | O28: 1 | P28: UnrealInsights | Q28: 501 | R28: 32 | S28: 3m 20s | T28: 3m 25s | U28: Group-2/Quad-Agent-8-Core-UnrealInsights-Target-1.uba | X28: 8 | Y28: 2 | Z28: 1 | AA28: UnrealPackageTool | AB28: 65 | AC28: 32 | AD28: 1m 26s | AE28: 1m 30s | AF28: Group-2/Quad-Agent-8-Core-UnrealPackageTool-Target-1.uba
B29: 8 | C29: 1 | D29: 2 | E29: UE5 | F29: 7914 | G29: 32 | H29: 35m 33s | I29: 41m 46s | J29: Group-1/Quad-Agent-8-Core-UE5-Target-2.uba | M29: 8 | N29: 1 | O29: 2 | P29: UnrealInsights | Q29: 501 | R29: 32 | S29: 3m 2s | T29: 3m 8s | U29: Group-1/Quad-Agent-8-Core-UnrealInsights-Target-2.uba | X29: 8 | Y29: 1 | Z29: 2 | AA29: UnrealPackageTool | AB29: 65 | AC29: 32 | AD29: 1m 20s | AE29: 1m 23s | AF29: Group-1/Quad-Agent-8-Core-UnrealPackageTool-Target-2.uba
B30: 8 | C30: 2 | D30: 2 | E30: UE5 | F30: 7914 | G30: 32 | H30: 38m 30s | I30: 44m 55s | J30: Group-2/Quad-Agent-8-Core-UE5-Target-2.uba | M30: 8 | N30: 2 | O30: 2 | P30: UnrealInsights | Q30: 501 | R30: 32 | S30: 2m 55s | T30: 3m 1s | U30: Group-2/Quad-Agent-8-Core-UnrealInsights-Target-2.uba | X30: 8 | Y30: 2 | Z30: 2 | AA30: UnrealPackageTool | AB30: 65 | AC30: 32 | AD30: 1m 24s | AE30: 1m 28s | AF30: Group-2/Quad-Agent-8-Core-UnrealPackageTool-Target-2.uba
B31: 16 | C31: 1 | D31: 1 | E31: UE5 | F31: 7914 | G31: 64 | H31: 29m 32s | I31: 35m 47s | J31: Group-1/Quad-Agent-16-Core-UE5-Target-1.uba | M31: 16 | N31: 1 | O31: 1 | P31: UnrealInsights | Q31: 501 | R31: 64 | S31: 2m 9s | T31: 2m 47s | U31: Group-1/Quad-Agent-16-Core-UnrealInsights-Target-1.uba | X31: 16 | Y31: 1 | Z31: 1 | AA31: UnrealPackageTool | AB31: 65 | AC31: 64 | AD31: 1m 22s | AE31: 1m 26s | AF31: Group-1/Quad-Agent-16-Core-UnrealPackageTool-Target-1.uba
B32: 16 | C32: 2 | D32: 1 | E32: UE5 | F32: 7914 | G32: 64 | H32: 30m 1s | I32: 36m 34s | J32: Group-2/Quad-Agent-16-Core-UE5-Target-1.uba | M32: 16 | N32: 2 | O32: 1 | P32: UnrealInsights | Q32: 501 | R32: 64 | S32: 2m 48s | T32: 3m 32s | U32: Group-2/Quad-Agent-16-Core-UnrealInsights-Target-1.uba | X32: 16 | Y32: 2 | Z32: 1 | AA32: UnrealPackageTool | AB32: 65 | AC32: 64 | AD32: 1m 24s | AE32: 1m 28s | AF32: Group-2/Quad-Agent-16-Core-UnrealPackageTool-Target-1.uba
B33: 16 | C33: 1 | D33: 2 | E33: UE5 | F33: 7914 | G33: 64 | H33: 27m 33s | I33: 33m 53s | J33: Lost | M33: 16 | N33: 1 | O33: 2 | P33: UnrealInsights | Q33: 501 | R33: 64 | S33: 2m 04s | T33: 2m 10s | U33: Group-1/Quad-Agent-16-Core-UnrealInsights-Target-2.uba | X33: 16 | Y33: 1 | Z33: 2 | AA33: UnrealPackageTool | AB33: 65 | AC33: 64 | AD33: 1m 15s | AE33: 1m 18s | AF33: Group-1/Quad-Agent-16-Core-UnrealPackageTool-Target-2.uba
B34: 16 | C34: 2 | D34: 2 | E34: UE5 | F34: 7914 | G34: 64 | H34: 30m 42s | I34: 37m 17s | J34: Group-2/Quad-Agent-16-Core-UE5-Target-2.uba | M34: 16 | N34: 2 | O34: 2 | P34: UnrealInsights | Q34: 501 | R34: 64 | S34: 2m 49s | T34: 3m 27s | U34: Group-2/Quad-Agent-16-Core-UnrealInsights-Target-2.uba | X34: 16 | Y34: 2 | Z34: 2 | AA34: UnrealPackageTool | AB34: 65 | AC34: 64 | AD34: 1m 20s | AE34: 1m 24s | AF34: Group-2/Quad-Agent-16-Core-UnrealPackageTool-Target-2.uba
B35: 24 | C35: 1 | D35: 1 | E35: UE5 | F35: 7914 | G35: 96 | H35: 24m 18s | I35: 30m 35s | J35: Group-1/Quad-Agent-24-Core-UE5-Target-1.uba | M35: 24 | N35: 1 | O35: 1 | P35: UnrealInsights | Q35: 501 | R35: 96 | S35: 2m 16s | T35: 2m 54s | U35: Group-1/Quad-Agent-24-Core-UnrealInsights-Target-1.uba | X35: 24 | Y35: 1 | Z35: 1 | AA35: UnrealPackageTool | AB35: 65 | AC35: 96 | AD35: 1m 18s | AE35: 1m 22s | AF35: Group-1/Quad-Agent-24-Core-UnrealPackageTool-Target-1.uba
... B38: 24 | C38: 2 | D38: 2 | E38: UE5 | F38: 7914 | G38: 96 | H38: 25m 52s | I38: 32m 12s | J38: Group-2/Quad-Agent-24-Core-UE5-Target-2.uba | M38: 24 | N38: 2 | O38: 2 | P38: UnrealInsights | Q38: 501 | R38: 96 | S38: 2m 15s | T38: 2m 21s | U38: Group-2/Quad-Agent-24-Core-UnrealInsights-Target-2.uba | X38: 24 | Y38: 2 | Z38: 2 | AA38: UnrealPackageTool | AB38: 65 | AC38: 96 | AD38: 1m 25s | AE38: 1m 30s | AF38: Group-2/Quad-Agent-24-Core-UnrealPackageTool-Target-2.uba
B39: RAM (GB) | C39: Group | D39: Run | E39: Target | F39: Actions | G39: Total Cores | H39: UBAVisualizer (Session) Time | I39: VisualStudio Time | J39: Trace | M39: RAM | N39: Group | O39: Run | P39: Target | Q39: Actions | R39: Total Cores | S39: UBAVisualizer (Session) Time | T39: VisualStudio Time | U39: Trace | X39: RAM | Y39: Group | Z39: Run | AA39: Target | AB39: Actions | AC39: Total Cores | AD39: UBAVisualizer (Session) Time | AE39: VisualStudio Time | AF39: Trace
A40: Quad Agent (RAM Tests) | B40: 1 | C40: 1 | D40: 1 | E40: UE5 | F40: 7914 | G40: 32 | H40: 2h 53m 46s | I40: 3h 0m 4s | J40: Group-1/RAM-Test-1GB-UE5-Target-1.uba | L40: Quad Agent (RAM Tests) | M40: 1 | N40: 1 | O40: 1 | P40: UnrealInsights | Q40: 501 | R40: 32 | S40: 10m 45s | T40: 11m 24s | U40: Group-1/RAM-Test-1GB-UnrealInsights-Target-1.uba | W40: Quad Agent (RAM Tests) | X40: 1 | Y40: 1 | Z40: 1 | AA40: UnrealPackageTool | AB40: 65 | AC40: 32 | AD40: 2m 38s | AE40: 2m 43s | AF40: Group-1/RAM-Test-1GB-UnrealPackageTool-Target-1.uba
B41: 1 | C41: 2 | D41: 1 | E41: UE5 | F41: 7914 | G41: 32 | H41: 3h 29m 31s | I41: 3h 36m 13s | J41: Group-2/RAM-Test-1GB-UE5-Target-1.uba | M41: 1 | N41: 2 | O41: 1 | P41: UnrealInsights | Q41: 501 | R41: 32 | S41: 10m 26s | T41: 11m 05s | U41: Lost | X41: 1 | Y41: 2 | Z41: 1 | AA41: UnrealPackageTool | AB41: 65 | AC41: 32 | AD41: 3m 29s | AE41: 3m 33s | AF41: Group-2/RAM-Test-1GB-UnrealPackageTool-Target-1.uba
B42: 1 | C42: 1 | D42: 2 | E42: UE5 | F42: 7914 | G42: 32 | H42: 2h 47m 42s | I42: 2h 53m 50s | J42: Group-1/RAM-Test-1GB-UE5-Target-2.uba | M42: 1 | N42: 1 | O42: 2 | P42: UnrealInsights | Q42: 501 | R42: 32 | S42: 7m 56s | T42: 8m 3s | U42: Group-1/RAM-Test-1GB-UnrealInsights-Target-2.uba | X42: 1 | Y42: 1 | Z42: 2 | AA42: UnrealPackageTool | AB42: 65 | AC42: 32 | AD42: 2m 31s | AE42: 2m 35s | AF42: Group-1/RAM-Test-1GB-UnrealPackageTool-Target-2.uba
B43: 1 | C43: 2 | D43: 2 | E43: UE5 | F43: 7914 | G43: 32 | H43: 3h 25m 46s | I43: 3h 32m 15s | J43: Group-2/RAM-Test-1GB-UE5-Target-2.uba | M43: 1 | N43: 2 | O43: 2 | P43: UnrealInsights | Q43: 501 | R43: 32 | S43: 9m 47s | T43: 9m 55s | U43: Group-2/RAM-Test-1GB-UnrealInsights-Target-2.uba | X43: 1 | Y43: 2 | Z43: 2 | AA43: UnrealPackageTool | AB43: 65 | AC43: 32 | AD43: 2m 56s | AE43: 3m | AF43: Group-2/RAM-Test-1GB-UnrealPackageTool-Target-2.uba
B44: 2 | C44: 1 | D44: 1 | E44: UE5 | F44: 7914 | G44: 32 | H44: 2h 55m 36s | I44: 3h 1m 34s | J44: Group-1/RAM-Test-2GB-UE5-Target-1.uba | M44: 2 | N44: 1 | O44: 1 | P44: UnrealInsights | Q44: 501 | R44: 32 | S44: 7m 35s | T44: 7m 41s | U44: Group-1/RAM-Test-2GB-UnrealInsights-Target-1.uba | X44: 2 | Y44: 1 | Z44: 1 | AA44: UnrealPackageTool | AB44: 65 | AC44: 32 | AD44: 2m 22s | AE44: 2m 26s | AF44: Group-1/RAM-Test-2GB-UnrealPackageTool-Target-1.uba
B45: 2 | C45: 2 | D45: 1 | E45: UE5 | F45: 7914 | G45: 32 | H45: 3h 22m 30s | I45: 3h 28m 35s | J45: Group-2/RAM-Test-2GB-UE5-Target-1.uba | M45: 2 | N45: 2 | O45: 1 | P45: UnrealInsights | Q45: 501 | R45: 32 | S45: 8m 50s | T45: 8m 57s | U45: Group-2/RAM-Test-2GB-UnrealInsights-Target-1.uba | X45: 2 | Y45: 2 | Z45: 1 | AA45: UnrealPackageTool | AB45: 65 | AC45: 32 | AD45: 2m 37s | AE45: 2m 41s | AF45: Group-2/RAM-Test-2GB-UnrealPackageTool-Target-1.uba
B46: 2 | C46: 1 | D46: 2 | E46: UE5 | F46: 7914 | G46: 32 | H46: 2h 44m 41s | I46: 2h 50m 56s | J46: Group-1/RAM-Test-2GB-UE5-Target-2.uba | M46: 2 | N46: 1 | O46: 2 | P46: UnrealInsights | Q46: 501 | R46: 32 | S46: 7m 9s | T46: 7m 15s | U46: Group-1/RAM-Test-2GB-UnrealInsights-Target-2.uba | X46: 2 | Y46: 1 | Z46: 2 | AA46: UnrealPackageTool | AB46: 65 | AC46: 32 | AD46: 2m 40s | AE46: 2m 44s | AF46: Group-1/RAM-Test-2GB-UnrealPackageTool-Target-2.uba
B47: 2 | C47: 2 | D47: 2 | E47: UE5 | F47: 7914 | G47: 32 | H47: 3h 16m 27s | I47: 3h 23m 2s | J47: Group-2/RAM-Test-2GB-UE5-Target-2.uba | M47: 2 | N47: 2 | O47: 2 | P47: UnrealInsights | Q47: 501 | R47: 32 | S47: 8m 21s | T47: 8m 27s | U47: Group-2/RAM-Test-2GB-UnrealInsights-Target-2.uba | X47: 2 | Y47: 2 | Z47: 2 | AA47: UnrealPackageTool | AB47: 65 | AC47: 32 | AD47: 2m 45s | AE47: 2m 49s | AF47: Group-2/RAM-Test-2GB-UnrealPackageTool-Target-2.uba
B48: 4 | C48: 1 | D48: 1 | E48: UE5 | F48: 7914 | G48: 32 | H48: 2h 50m 28s | I48: 2h 56m 51s | J48: Group-1/RAM-Test-4GB-UE5-Target-1.uba | M48: 4 | N48: 1 | O48: 1 | P48: UnrealInsights | Q48: 501 | R48: 32 | S48: 3m 5s | T48: 3m 42s | U48: Group-1/RAM-Test-4GB-UnrealInsights-Target-1.uba | X48: 4 | Y48: 1 | Z48: 1 | AA48: UnrealPackageTool | AB48: 65 | AC48: 32 | AD48: 1m 33s | AE48: 1m 37s | AF48: Group-1/RAM-Test-4GB-UnrealPackageTool-Target-1.uba
...

Sheet Parsed Data
A1: Agents | B1: Cores/Agent | C1: Group | D1: Run | E1: Target | F1: Total Cores | G1: UBAVisualizer (Session) Time | H1: VisualStudio Time | J1: RAM | K1: Group | L1: Run | M1: Target | N1: UBAVisualizer (Session) Time | O1: VisualStudio Time
A2: 0 | B2: 0 | C2: 1 | D2: 1 | E2: UE5 | F2: 0 | G2: 9999 | H2: 10056 | J2: 1 | K2: 1 | L2: 1 | M2: UE5 | N2: 10426 | O2: 10804
A3: 0 | B3: 0 | C3: 2 | D3: 1 | E3: UE5 | F3: 0 | G3: 11316 | H3: 11370 | J3: 1 | K3: 2 | L3: 1 | M3: UE5 | N3: 12571 | O3: 12973
A4: 0 | B4: 0 | C4: 1 | D4: 2 | E4: UE5 | F4: 0 | G4: 9977 | H4: 10027 | J4: 1 | K4: 1 | L4: 2 | M4: UE5 | N4: 10062 | O4: 10430
A5: 0 | B5: 0 | C5: 2 | D5: 2 | E5: UE5 | F5: 0 | G5: 11231 | H5: 11287 | J5: 1 | K5: 2 | L5: 2 | M5: UE5 | N5: 12346 | O5: 12735
A6: 1 | B6: 32 | C6: 1 | D6: 1 | E6: UE5 | F6: 32 | G6: 1863 | H6: 1898 | J6: 2 | K6: 1 | L6: 1 | M6: UE5 | N6: 10536 | O6: 10894
A7: 1 | B7: 32 | C7: 2 | D7: 1 | E7: UE5 | F7: 32 | G7: 2147 | H7: 2199 | J7: 2 | K7: 2 | L7: 1 | M7: UE5 | N7: 12150 | O7: 12515
A8: 1 | B8: 32 | C8: 1 | D8: 2 | E8: UE5 | F8: 32 | G8: 1787 | H8: 1833 | J8: 2 | K8: 1 | L8: 2 | M8: UE5 | N8: 9881 | O8: 10256
A9: 1 | B9: 32 | C9: 2 | D9: 2 | E9: UE5 | F9: 32 | G9: 2066 | H9: 2113 | J9: 2 | K9: 2 | L9: 2 | M9: UE5 | N9: 11787 | O9: 12182
A10: 1 | B10: 16 | C10: 1 | D10: 1 | E10: UE5 | F10: 16 | G10: 3018 | H10: 3071 | J10: 4 | K10: 1 | L10: 1 | M10: UE5 | N10: 10228 | O10: 10611
A11: 1 | B11: 16 | C11: 2 | D11: 1 | E11: UE5 | F11: 16 | G11: 3120 | H11: 3171 | J11: 4 | K11: 2 | L11: 1 | M11: UE5 | N11: 11222 | O11: 11619
A12: 1 | B12: 16 | C12: 1 | D12: 2 | E12: UE5 | F12: 16 | G12: 3034 | H12: 3409 | J12: 4 | K12: 1 | L12: 2 | M12: UE5 | N12: 9723 | O12: 10097
A13: 1 | B13: 16 | C13: 2 | D13: 2 | E13: UE5 | F13: 16 | G13: 3133 | H13: 3485 | J13: 4 | K13: 2 | L13: 2 | M13: UE5 | N13: 10983 | O13: 11379
... A73: 1 | B73: 8 | C73: 2 | D73: 2 | E73: UnrealInsights | F73: 8 | G73: 268 | H73: 275 | J73: 24 | K73: 2 | L73: 2 | M73: UnrealPackageTool | N73: 94 | O73: 98
A74: 1 | B74: 4 | C74: 1 | D74: 1 | E74: UnrealInsights | F74: 4 | G74: 319 | H74: 332
A75: 1 | B75: 4 | C75: 2 | D75: 1 | E75: UnrealInsights | F75: 4 | G75: 357 | H75: 367
A76: 1 | B76: 4 | C76: 1 | D76: 2 | E76: UnrealInsights | F76: 4 | G76: 323 | H76: 329
A77: 1 | B77: 4 | C77: 2 | D77: 2 | E77: UnrealInsights | F77: 4 | G77: 336 | H77: 343
A78: 4 | B78: 4 | C78: 1 | D78: 1 | E78: UnrealInsights | F78: 16 | G78: 243 | H78: 248
A79: 4 | B79: 4 | C79: 2 | D79: 1 | E79: UnrealInsights | F79: 16 | G79: 234 | H79: 239
A80: 4 | B80: 4 | C80: 1 | D80: 2 | E80: UnrealInsights | F80: 16 | G80: 231 | H80: 236
A81: 4 | B81: 4 | C81: 2 | D81: 2 | E81: UnrealInsights | F81: 16 | G81: 231 | H81: 237
A82: 4 | B82: 8 | C82: 1 | D82: 1 | E82: UnrealInsights | F82: 32 | G82: 208 | H82: 214
A83: 4 | B83: 8 | C83: 2 | D83: 1 | E83: UnrealInsights | F83: 32 | G83: 200 | H83: 205
A84: 4 | B84: 8 | C84: 1 | D84: 2 | E84: UnrealInsights | F84: 32 | G84: 182 | H84: 188
A85: 4 | B85: 8 | C85: 2 | D85: 2 | E85: UnrealInsights | F85: 32 | G85: 175 | H85: 181
... A157: 8 | B157: 12 | C157: 2 | D157: 2 | E157: UnrealPackageTool | F157: 96 | G157: 94 | H157: 97

Sheet Core Count Scaling
A1: Target: | B1: Number of Remote Agents: | S1: Reciprocal graph | U1: Measured | W1: Measured @ 1 agent | Y1: Measured @ 4 agents | AA1: Measured @ 8 agents
A2: UE5 | B2: 1 | C2: Cores for calculation | D2: Time | E2: Deviation | G2: Speedup | H2: Deviation | K2: Evolutionary Solver | L2: A (Asymptote) | M2: B (distributable tasks) | N2: C (initiator contribution) | S2: Graph points to plot | U2: Negative | V2: Positive | W2: Negative | X2: Positive | Y2: Negative | Z2: Positive | AA2: Negative | AB2: Positive
E3: Negative | F3: Positive | H3: Negative | I3: Positive | L3: {=INDEX(DropDowns!G2:G10, MATCH(A2&B2, DropDowns!E2:E10&DropDowns!F2:F10, 0))} -> 795.58 | M3: {=INDEX(DropDowns!H2:H10, MATCH(A2&B2, DropDowns!E2:E10&DropDowns!F2:F10, 0))} -> 51979.92 | N3: {=INDEX(DropDowns!I2:I10, MATCH(A2&B2, DropDowns!E2:E10&DropDowns!F2:F10, 0))} -> 5.27 | O3: Minimal bound (restricting overestimation) | P3: Maximal bound (restricting underestimation) | Q3: Evolutionary algorithm penalty for overestimation | S3: 0 | T3: =$L$3+($M$3/($S3+$N$3)) -> 10658.942 | U3: {=_xlfn.IFS($B$2=1, W3, $B$2=4, Y3, $B$2=8, AA3)} -> 681.94243 | V3: {=_xlfn.IFS($B$2=1, X3, $B$2=4, Z3, $B$2=8, AB3)} -> 657.05757 | W3: =$T$3-($D$4-$E$4) -> 681.94243 | X3: =($D$4+$F$4)-$T$3 -> 657.05757 | Y3: =$T$3-($D$4-$E$4) -> 681.94243 | Z3: =($D$4+$F$4)-$T$3 -> 657.05757 | AA3: =$T$3-($D$4-$E$4) -> 681.94243 | AB3: =($D$4+$F$4)-$T$3 -> 657.05757
B4: 0 cores/agent (Baseline) | C4: 0 | D4: =AVERAGEIFS(CoreParsedData[UBAVisualizer (Session) Time], CoreParsedData[Agents], $C$4, CoreParsedData[Cores/Agent], C4, CoreParsedData[Target], $A$2) -> 10630.75 | E4: =D4-_xlfn.MINIFS(CoreParsedData[UBAVisualizer (Session) Time], CoreParsedData[Agents], 0, CoreParsedData[Cores/Agent], C4, CoreParsedData[Target], $A$2) -> 653.75 | F4: =_xlfn.MAXIFS(CoreParsedData[UBAVisualizer (Session) Time], CoreParsedData[Agents], 0, CoreParsedData[Cores/Agent], C4, CoreParsedData[Target], $A$2)-D4 -> 685.25 | G4: 1 | H4: 0 | I4: 0 | K4: Cores | L4: Measured value | M4: Predicted Value | N4: Error^2 | S4: 2 | T4: =$L$3+($M$3/($S4+$N$3)) -> 7945.5002 | U4: {=_xlfn.IFS($B$2=1, W4, $B$2=4, Y4, $B$2=8, AA4)} -> 0 | V4: {=_xlfn.IFS($B$2=1, X4, $B$2=4, Z4, $B$2=8, AB4)} -> 0
B5: 4 cores/agent | C5: 4 | D5: =AVERAGEIFS(CoreParsedData[UBAVisualizer (Session) Time], CoreParsedData[Agents], $B$2, CoreParsedData[Cores/Agent], C5, CoreParsedData[Target], $A$2) -> 6522 | E5: =D5-_xlfn.MINIFS(CoreParsedData[UBAVisualizer (Session) Time], CoreParsedData[Agents], $B$2, CoreParsedData[Cores/Agent], C5, CoreParsedData[Target], $A$2) -> 337 | F5: =_xlfn.MAXIFS(CoreParsedData[UBAVisualizer (Session) Time], CoreParsedData[Agents], $B$2, CoreParsedData[Cores/Agent], C5, CoreParsedData[Target], $A$2)-D5 -> 316 | G5: =$D$4/D5 -> 1.6299831 | H5: =($D$4/D5)-($D$4/(D5+F5)) -> 0.075325339 | I5: =($D$4/(D5-E5))-($D$4/D5) -> 0.088812339 | K5: 0 | L5: =D4 -> 10630.75 | M5: =$L$3+($M$3/(1*$K5+$N$3)) -> 10658.942 | N5: =_xlfn.IFNA((M5-L5)^2, 0) -> 794.81304 | O5: =_xlfn.IFNA(D4-E4, 0) -> 9977 | P5: =_xlfn.IFNA(D4+F4, 999999) -> 11316 | Q5: =IF(AND(NOT(ISNA(L5)), M5 < O5), (O5 - L5)^2*1000000, 0) -> 0 | S5: 4 | T5: =$L$3+($M$3/($S5+$N$3)) -> 6402.9069 | U5: {=_xlfn.IFS($B$2=1, W5, $B$2=4, Y5, $B$2=8, AA5)} -> 217.90686 | V5: {=_xlfn.IFS($B$2=1, X5, $B$2=4, Z5, $B$2=8, AB5)} -> 435.09314 | W5: =$T$5-($D$5-$E$5) -> 217.90686 | X5: =($D$5+$F$5)-$T$5 -> 435.09314
B6: 8 cores/agent | C6: 8 | D6: =AVERAGEIFS(CoreParsedData[UBAVisualizer (Session) Time], CoreParsedData[Agents], $B$2, CoreParsedData[Cores/Agent], C6, CoreParsedData[Target], $A$2) -> 4758 | E6: =D6-_xlfn.MINIFS(CoreParsedData[UBAVisualizer (Session) Time], CoreParsedData[Agents], $B$2, CoreParsedData[Cores/Agent], C6, CoreParsedData[Target], $A$2) -> 208 | F6: =_xlfn.MAXIFS(CoreParsedData[UBAVisualizer (Session) Time], CoreParsedData[Agents], $B$2, CoreParsedData[Cores/Agent], C6, CoreParsedData[Target], $A$2)-D6 -> 275 | G6: =$D$4/D6 -> 2.2342896 | H6: =($D$4/D6)-($D$4/(D6+F6)) -> 0.1220802 | I6: =($D$4/(D6-E6))-($D$4/D6) -> 0.10213895 | K6: 4 | L6: =D5 -> 6522 | M6: =$L$3+($M$3/(1*$K6+$N$3)) -> 6402.9069 | N6: =_xlfn.IFNA((M6-L6)^2, 0) -> 14183.176 | O6: =_xlfn.IFNA(D5-E5, 0) -> 6185 | P6: =_xlfn.IFNA(D5+F5, 999999) -> 6838 | Q6: =IF(AND(NOT(ISNA(L6)), M6 < O6), (O6 - L6)^2*1000000, 0) -> 0 | S6: 6 | T6: =$L$3+($M$3/($S6+$N$3)) -> 5407.8178 | U6: {=_xlfn.IFS($B$2=1, W6, $B$2=4, Y6, $B$2=8, AA6)} -> 0 | V6: {=_xlfn.IFS($B$2=1, X6, $B$2=4, Z6, $B$2=8, AB6)} -> 0
B7: 12 cores/agent | C7: 12 | D7: =IFERROR(AVERAGEIFS(CoreParsedData[UBAVisualizer (Session) Time], CoreParsedData[Agents], $B$2, CoreParsedData[Cores/Agent], C7, CoreParsedData[Target], $A$2), NA()) -> #N/A | E7: =D7-_xlfn.MINIFS(CoreParsedData[UBAVisualizer (Session) Time], CoreParsedData[Agents], $B$2, CoreParsedData[Cores/Agent], C7, CoreParsedData[Target], $A$2) -> #N/A | F7: =_xlfn.MAXIFS(CoreParsedData[UBAVisualizer (Session) Time], CoreParsedData[Agents], $B$2, CoreParsedData[Cores/Agent], C7, CoreParsedData[Target], $A$2)-D7 -> #N/A | G7: =$D$4/D7 -> #N/A | H7: =($D$4/D7)-($D$4/(D7+F7)) -> #N/A | I7: =($D$4/(D7-E7))-($D$4/D7) -> #N/A | K7: 8 | L7: =D6 -> 4758 | M7: =$L$3+($M$3/(1*$K7+$N$3)) -> 4712.6802 | N7: =_xlfn.IFNA((M7-L7)^2, 0) -> 2053.8819 | O7: =_xlfn.IFNA(D6-E6, 0) -> 4550 | P7: =_xlfn.IFNA(D6+F6, 999999) -> 5033 | Q7: =IF(AND(NOT(ISNA(L7)), M7 < O7), (O7 - L7)^2*1000000, 0) -> 0 | S7: 8 | T7: =$L$3+($M$3/($S7+$N$3)) -> 4712.6802 | U7: {=_xlfn.IFS($B$2=1, W7, $B$2=4, Y7, $B$2=8, AA7)} -> 162.68023 | V7: {=_xlfn.IFS($B$2=1, X7, $B$2=4, Z7, $B$2=8, AB7)} -> 320.31977 | W7: =$T$7-($D$6-$E$6) -> 162.68023 | X7: =($D$6+$F$6)-$T$7 -> 320.31977
B8: 16 cores/agent | C8: 16 | D8: =IFERROR(AVERAGEIFS(CoreParsedData[UBAVisualizer (Session) Time], CoreParsedData[Agents], $B$2, CoreParsedData[Cores/Agent], C8, CoreParsedData[Target], $A$2), NA()) -> 3076.25 | E8: =D8-_xlfn.MINIFS(CoreParsedData[UBAVisualizer (Session) Time], CoreParsedData[Agents], $B$2, CoreParsedData[Cores/Agent], C8, CoreParsedData[Target], $A$2) -> 58.25 | F8: =_xlfn.MAXIFS(CoreParsedData[UBAVisualizer (Session) Time], CoreParsedData[Agents], $B$2, CoreParsedData[Cores/Agent], C8, CoreParsedData[Target], $A$2)-D8 -> 56.75 | G8: =$D$4/D8 -> 3.4557497 | H8: =($D$4/D8)-($D$4/(D8+F8)) -> 0.062596168 | I8: =($D$4/(D8-E8))-($D$4/D8) -> 0.066698946 | K8: 12 | L8: =D7 -> #N/A | M8: =$L$3+($M$3/(1*$K8+$N$3)) -> 3805.419 | N8: =_xlfn.IFNA((M8-L8)^2, 0) -> 0 | O8: =_xlfn.IFNA(D7-E7, 0) -> 0 | P8: =_xlfn.IFNA(D7+F7, 999999) -> 999999 | Q8: =IF(AND(NOT(ISNA(L8)), M8 < O8), (O8 - L8)^2*1000000, 0) -> 0 | S8: 10 | T8: =$L$3+($M$3/($S8+$N$3)) -> 4199.635 | U8: {=_xlfn.IFS($B$2=1, W8, $B$2=4, Y8, $B$2=8, AA8)} -> 0 | V8: {=_xlfn.IFS($B$2=1, X8, $B$2=4, Z8, $B$2=8, AB8)} -> 0
B9: 24 cores/agent | C9: 24 | D9: =IFERROR(AVERAGEIFS(CoreParsedData[UBAVisualizer (Session) Time], CoreParsedData[Agents], $B$2, CoreParsedData[Cores/Agent], C9, CoreParsedData[Target], $A$2), NA()) -> #N/A | E9: =D9-_xlfn.MINIFS(CoreParsedData[UBAVisualizer (Session) Time], CoreParsedData[Agents], $B$2, CoreParsedData[Cores/Agent], C9, CoreParsedData[Target], $A$2) -> #N/A | F9: =_xlfn.MAXIFS(CoreParsedData[UBAVisualizer (Session) Time], CoreParsedData[Agents], $B$2, CoreParsedData[Cores/Agent], C9, CoreParsedData[Target], $A$2)-D9 -> #N/A | G9: =$D$4/D9 -> #N/A | H9: =($D$4/D9)-($D$4/(D9+F9)) -> #N/A | I9: =($D$4/(D9-E9))-($D$4/D9) -> #N/A | K9: 16 | L9: =D8 -> 3076.25 | M9: =$L$3+($M$3/(1*$K9+$N$3)) -> 3239.3938 | N9: =_xlfn.IFNA((M9-L9)^2, 0) -> 26615.907 | O9: =_xlfn.IFNA(D8-E8, 0) -> 3018 | P9: =_xlfn.IFNA(D8+F8, 999999) -> 3133 | Q9: =IF(AND(NOT(ISNA(L9)), M9 < O9), (O9 - L9)^2*1000000, 0) -> 0 | S9: 12 | T9: =$L$3+($M$3/($S9+$N$3)) -> 3805.419 | U9: {=_xlfn.IFS($B$2=1, W9, $B$2=4, Y9, $B$2=8, AA9)} -> #N/A | V9: {=_xlfn.IFS($B$2=1, X9, $B$2=4, Z9, $B$2=8, AB9)} -> #N/A | W9: =$T$9-($D$7-$E$7) -> #N/A | X9: =($D$7+$F$7)-$T$9 -> #N/A
B10: 32 cores/agent | C10: 32 | D10: =IFERROR(AVERAGEIFS(CoreParsedData[UBAVisualizer (Session) Time], CoreParsedData[Agents], $B$2, CoreParsedData[Cores/Agent], C10, CoreParsedData[Target], $A$2), NA()) -> 1965.75 | E10: =D10-_xlfn.MINIFS(CoreParsedData[UBAVisualizer (Session) Time], CoreParsedData[Agents], $B$2, CoreParsedData[Cores/Agent], C10, CoreParsedData[Target], $A$2) -> 178.75 | F10: =_xlfn.MAXIFS(CoreParsedData[UBAVisualizer (Session) Time], CoreParsedData[Agents], $B$2, CoreParsedData[Cores/Agent], C10, CoreParsedData[Target], $A$2)-D10 -> 181.25 | G10: =$D$4/D10 -> 5.4079868 | H10: =($D$4/D10)-($D$4/(D10+F10)) -> 0.4565429 | I10: =($D$4/(D10-E10))-($D$4/D10) -> 0.54094999 | K10: 24 | L10: =D9 -> #N/A | M10: =$L$3+($M$3/(1*$K10+$N$3)) -> 2571.457 | N10: =_xlfn.IFNA((M10-L10)^2, 0) -> 0 | O10: =_xlfn.IFNA(D9-E9, 0) -> 0 | P10: =_xlfn.IFNA(D9+F9, 999999) -> 999999 | Q10: =IF(AND(NOT(ISNA(L10)), M10 < O10), (O10 - L10)^2*1000000, 0) -> 0 | S10: 14 | T10: =$L$3+($M$3/($S10+$N$3)) -> 3493.033 | U10: {=_xlfn.IFS($B$2=1, W10, $B$2=4, Y10, $B$2=8, AA10)} -> 0 | V10: {=_xlfn.IFS($B$2=1, X10, $B$2=4, Z10, $B$2=8, AB10)} -> 0
B11: 64 cores/agent | C11: 64 | D11: =IFERROR(AVERAGEIFS(CoreParsedData[UBAVisualizer (Session) Time], CoreParsedData[Agents], $B$2, CoreParsedData[Cores/Agent], C11, CoreParsedData[Target], $A$2), NA()) -> 1594.75 | E11: =D11-_xlfn.MINIFS(CoreParsedData[UBAVisualizer (Session) Time], CoreParsedData[Agents], $B$2, CoreParsedData[Cores/Agent], C11, CoreParsedData[Target], $A$2) -> 48.75 | F11: =_xlfn.MAXIFS(CoreParsedData[UBAVisualizer (Session) Time], CoreParsedData[Agents], $B$2, CoreParsedData[Cores/Agent], C11, CoreParsedData[Target], $A$2)-D11 -> 21.25 | G11: =$D$4/D11 -> 6.6660919 | H11: =($D$4/D11)-($D$4/(D11+F11)) -> 0.087657458 | I11: =($D$4/(D11-E11))-($D$4/D11) -> 0.2102018 | K11: 32 | L11: =D10 -> 1965.75 | M11: =$L$3+($M$3/(1*$K11+$N$3)) -> 2190.2653 | N11: =_xlfn.IFNA((M11-L11)^2, 0) -> 50407.106 | O11: =_xlfn.IFNA(D10-E10, 0) -> 1787 | P11: =_xlfn.IFNA(D10+F10, 999999) -> 2147 | Q11: =IF(AND(NOT(ISNA(L11)), M11 < O11), (O11 - L11)^2*1000000, 0) -> 0 | S11: 16 | T11: =$L$3+($M$3/($S11+$N$3)) -> 3239.3938 | U11: {=_xlfn.IFS($B$2=1, W11, $B$2=4, Y11, $B$2=8, AA11)} -> 221.39382 | V11: {=_xlfn.IFS($B$2=1, X11, $B$2=4, Z11, $B$2=8, AB11)} -> -106.39382 | W11: =$T$11-($D$8-$E$8) -> 221.39382 | X11: =($D$8+$F$8)-$T$11 -> -106.39382 | Y11: =$T$11-($D$5-$E$5) -> -2945.6062 | Z11: =($D$5+$F$5)-$T$11 -> 3598.6062
K12: 64 | L12: =D11 -> 1594.75 | M12: =$L$3+($M$3/(1*$K12+$N$3)) -> 1545.9758 | N12: =_xlfn.IFNA((M12-L12)^2, 0) -> 2378.9185 | O12: =_xlfn.IFNA(D11-E11, 0) -> 1546 | P12: =_xlfn.IFNA(D11+F11, 999999) -> 1616 | Q12: =IF(AND(NOT(ISNA(L12)), M12 < O12), (O12 - L12)^2*1000000, 0) -> 2376562500 | S12: 18 | T12: =$L$3+($M$3/($S12+$N$3)) -> 3029.354 | U12: {=_xlfn.IFS($B$2=1, W12, $B$2=4, Y12, $B$2=8, AA12)} -> 0 | V12: {=_xlfn.IFS($B$2=1, X12, $B$2=4, Z12, $B$2=8, AB12)} -> 0
M13: Total Error^2: | N13: =SUM(N5:N12) -> 96433.802 | O13: Evolutionary Algorithm Target: | Q13: =N13 + SUM(Q5:Q12) -> 2.3766589e+09 | S13: 20 | T13: =$L$3+($M$3/($S13+$N$3)) -> 2852.5614 | U13: {=_xlfn.IFS($B$2=1, W13, $B$2=4, Y13, $B$2=8, AA13)} -> 0 | V13: {=_xlfn.IFS($B$2=1, X13, $B$2=4, Z13, $B$2=8, AB13)} -> 0
M14: RMSE: | N14: =SQRT(N13/COUNT(L5:L12)) -> 126.77658 | S14: 22 | T14: =$L$3+($M$3/($S14+$N$3)) -> 2701.701 | U14: {=_xlfn.IFS($B$2=1, W14, $B$2=4, Y14, $B$2=8, AA14)} -> 0 | V14: {=_xlfn.IFS($B$2=1, X14, $B$2=4, Z14, $B$2=8, AB14)} -> 0
M15: Deviation from global mean: | N15: {=N14/AVERAGE(IF(ISNUMBER(D4:D11), D4:D11))} -> 0.026645397 | S15: 24 | T15: =$L$3+($M$3/($S15+$N$3)) -> 2571.457 | U15: {=_xlfn.IFS($B$2=1, W15, $B$2=4, Y15, $B$2=8, AA15)} -> #N/A | V15: {=_xlfn.IFS($B$2=1, X15, $B$2=4, Z15, $B$2=8, AB15)} -> #N/A | W15: =$T$15-($D$9-$E$9) -> #N/A | X15: =($D$9+$F$9)-$T$15 -> #N/A
M16: Parallelization Percentile: | N16: =(M3/N3)/(L3+(M3/N3)) -> 0.92536032 | S16: 26 | T16: =$L$3+($M$3/($S16+$N$3)) -> 2457.8736 | U16: {=_xlfn.IFS($B$2=1, W16, $B$2=4, Y16, $B$2=8, AA16)} -> 0 | V16: {=_xlfn.IFS($B$2=1, X16, $B$2=4, Z16, $B$2=8, AB16)} -> 0
M17: Max Theoretical speedup: | N17: =D4/L3 -> 13.362264 | S17: 28 | T17: =$L$3+($M$3/($S17+$N$3)) -> 2357.9461 | U17: {=_xlfn.IFS($B$2=1, W17, $B$2=4, Y17, $B$2=8, AA17)} -> 0 | V17: {=_xlfn.IFS($B$2=1, X17, $B$2=4, Z17, $B$2=8, AB17)} -> 0
S18: 30 | T18: =$L$3+($M$3/($S18+$N$3)) -> 2269.3515 | U18: {=_xlfn.IFS($B$2=1, W18, $B$2=4, Y18, $B$2=8, AA18)} -> 0 | V18: {=_xlfn.IFS($B$2=1, X18, $B$2=4, Z18, $B$2=8, AB18)} -> 0
S19: 32 | T19: =$L$3+($M$3/($S19+$N$3)) -> 2190.2653 | U19: {=_xlfn.IFS($B$2=1, W19, $B$2=4, Y19, $B$2=8, AA19)} -> 403.26527 | V19: {=_xlfn.IFS($B$2=1, X19, $B$2=4, Z19, $B$2=8, AB19)} -> -43.26527 | W19: =$T$19-($D$10-$E$10) -> 403.26527 | X19: =($D$10+$F$10)-$T$19 -> -43.26527 | Y19: =$T$19-($D$6-$E$6) -> -2359.7347 | Z19: =($D$6+$F$6)-$T$19 -> 2842.7347 | AA19: =$T$19-($D$5-$E$5) -> -3994.7347 | AB19: =($D$5+$F$5)-$T$19 -> 4647.7347
S20: 34 | T20: =$L$3+($M$3/($S20+$N$3)) -> 2119.2347 | U20: {=_xlfn.IFS($B$2=1, W20, $B$2=4, Y20, $B$2=8, AA20)} -> 0 | V20: {=_xlfn.IFS($B$2=1, X20, $B$2=4, Z20, $B$2=8, AB20)} -> 0
S21: 36 | T21: =$L$3+($M$3/($S21+$N$3)) -> 2055.0886 | U21: {=_xlfn.IFS($B$2=1, W21, $B$2=4, Y21, $B$2=8, AA21)} -> 0 | V21: {=_xlfn.IFS($B$2=1, X21, $B$2=4, Z21, $B$2=8, AB21)} -> 0
S22: 38 | T22: =$L$3+($M$3/($S22+$N$3)) -> 1996.8724 | U22: {=_xlfn.IFS($B$2=1, W22, $B$2=4, Y22, $B$2=8, AA22)} -> 0 | V22: {=_xlfn.IFS($B$2=1, X22, $B$2=4, Z22, $B$2=8, AB22)} -> 0
S23: 40 | T23: =$L$3+($M$3/($S23+$N$3)) -> 1943.8 | U23: {=_xlfn.IFS($B$2=1, W23, $B$2=4, Y23, $B$2=8, AA23)} -> 0 | V23: {=_xlfn.IFS($B$2=1, X23, $B$2=4, Z23, $B$2=8, AB23)} -> 0
S24: 42 | T24: =$L$3+($M$3/($S24+$N$3)) -> 1895.2187 | U24: {=_xlfn.IFS($B$2=1, W24, $B$2=4, Y24, $B$2=8, AA24)} -> 0 | V24: {=_xlfn.IFS($B$2=1, X24, $B$2=4, Z24, $B$2=8, AB24)} -> 0
S25: 44 | T25: =$L$3+($M$3/($S25+$N$3)) -> 1850.5814 | U25: {=_xlfn.IFS($B$2=1, W25, $B$2=4, Y25, $B$2=8, AA25)} -> 0 | V25: {=_xlfn.IFS($B$2=1, X25, $B$2=4, Z25, $B$2=8, AB25)} -> 0
S26: 46 | T26: =$L$3+($M$3/($S26+$N$3)) -> 1809.4267 | U26: {=_xlfn.IFS($B$2=1, W26, $B$2=4, Y26, $B$2=8, AA26)} -> 0 | V26: {=_xlfn.IFS($B$2=1, X26, $B$2=4, Z26, $B$2=8, AB26)} -> 0
S27: 48 | T27: =$L$3+($M$3/($S27+$N$3)) -> 1771.3622 | U27: {=_xlfn.IFS($B$2=1, W27, $B$2=4, Y27, $B$2=8, AA27)} -> 0 | V27: {=_xlfn.IFS($B$2=1, X27, $B$2=4, Z27, $B$2=8, AB27)} -> 0 | Y27: =$T$27-($D$7-$E$7) -> #N/A | Z27: =($D$7+$F$7)-$T$27 -> #N/A
S28: 50 | T28: =$L$3+($M$3/($S28+$N$3)) -> 1736.0526 | U28: {=_xlfn.IFS($B$2=1, W28, $B$2=4, Y28, $B$2=8, AA28)} -> 0 | V28: {=_xlfn.IFS($B$2=1, X28, $B$2=4, Z28, $B$2=8, AB28)} -> 0
S29: 52 | T29: =$L$3+($M$3/($S29+$N$3)) -> 1703.2091 | U29: {=_xlfn.IFS($B$2=1, W29, $B$2=4, Y29, $B$2=8, AA29)} -> 0 | V29: {=_xlfn.IFS($B$2=1, X29, $B$2=4, Z29, $B$2=8, AB29)} -> 0
S30: 54 | T30: =$L$3+($M$3/($S30+$N$3)) -> 1672.5822 | U30: {=_xlfn.IFS($B$2=1, W30, $B$2=4, Y30, $B$2=8, AA30)} -> 0 | V30: {=_xlfn.IFS($B$2=1, X30, $B$2=4, Z30, $B$2=8, AB30)} -> 0
S31: 56 | T31: =$L$3+($M$3/($S31+$N$3)) -> 1643.9547 | U31: {=_xlfn.IFS($B$2=1, W31, $B$2=4, Y31, $B$2=8, AA31)} -> 0 | V31: {=_xlfn.IFS($B$2=1, X31, $B$2=4, Z31, $B$2=8, AB31)} -> 0
S32: 58 | T32: =$L$3+($M$3/($S32+$N$3)) -> 1617.1371 | U32: {=_xlfn.IFS($B$2=1, W32, $B$2=4, Y32, $B$2=8, AA32)} -> 0 | V32: {=_xlfn.IFS($B$2=1, X32, $B$2=4, Z32, $B$2=8, AB32)} -> 0
S33: 60 | T33: =$L$3+($M$3/($S33+$N$3)) -> 1591.963 | U33: {=_xlfn.IFS($B$2=1, W33, $B$2=4, Y33, $B$2=8, AA33)} -> 0 | V33: {=_xlfn.IFS($B$2=1, X33, $B$2=4, Z33, $B$2=8, AB33)} -> 0
S34: 62 | T34: =$L$3+($M$3/($S34+$N$3)) -> 1568.2858 | U34: {=_xlfn.IFS($B$2=1, W34, $B$2=4, Y34, $B$2=8, AA34)} -> 0 | V34: {=_xlfn.IFS($B$2=1, X34, $B$2=4, Z34, $B$2=8, AB34)} -> 0
S35: 64 | T35: =$L$3+($M$3/($S35+$N$3)) -> 1545.9758 | U35: {=_xlfn.IFS($B$2=1, W35, $B$2=4, Y35, $B$2=8, AA35)} -> -0.024157644 | V35: {=_xlfn.IFS($B$2=1, X35, $B$2=4, Z35, $B$2=8, AB35)} -> 70.024158 | W35: =$T$35-($D$11-$E$11) -> -0.024157644 | X35: =($D$11+$F$11)-$T$35 -> 70.024158 | Y35: =$T$35-($D$8-$E$8) -> -1472.0242 | Z35: =($D$8+$F$8)-$T$35 -> 1587.0242 | AA35: =$T$35-($D$6-$E$6) -> -3004.0242 | AB35: =($D$6+$F$6)-$T$35 -> 3487.0242
S36: 66 | T36: =$L$3+($M$3/($S36+$N$3)) -> 1524.918 | U36: {=_xlfn.IFS($B$2=1, W36, $B$2=4, Y36, $B$2=8, AA36)} -> 0 | V36: {=_xlfn.IFS($B$2=1, X36, $B$2=4, Z36, $B$2=8, AB36)} -> 0
S37: 68 | T37: =$L$3+($M$3/($S37+$N$3)) -> 1505.0098 | U37: {=_xlfn.IFS($B$2=1, W37, $B$2=4, Y37, $B$2=8, AA37)} -> 0 | V37: {=_xlfn.IFS($B$2=1, X37, $B$2=4, Z37, $B$2=8, AB37)} -> 0
S38: 70 | T38: =$L$3+($M$3/($S38+$N$3)) -> 1486.1595 | U38: {=_xlfn.IFS($B$2=1, W38, $B$2=4, Y38, $B$2=8, AA38)} -> 0 | V38: {=_xlfn.IFS($B$2=1, X38, $B$2=4, Z38, $B$2=8, AB38)} -> 0
S39: 72 | T39: =$L$3+($M$3/($S39+$N$3)) -> 1468.2851 | U39: {=_xlfn.IFS($B$2=1, W39, $B$2=4, Y39, $B$2=8, AA39)} -> 0 | V39: {=_xlfn.IFS($B$2=1, X39, $B$2=4, Z39, $B$2=8, AB39)} -> 0
S40: 74 | T40: =$L$3+($M$3/($S40+$N$3)) -> 1451.3126 | U40: {=_xlfn.IFS($B$2=1, W40, $B$2=4, Y40, $B$2=8, AA40)} -> 0 | V40: {=_xlfn.IFS($B$2=1, X40, $B$2=4, Z40, $B$2=8, AB40)} -> 0
...

Sheet Agent Count Scaling
A1: Target: | B1: Number of Cores per Remote Agent: | S1: Reciprocal graph | U1: Deviation
A2: UE5 | B2: 4 | C2: Agents | D2: Time | E2: Deviation | G2: Speedup | H2: Deviation | K2: Evolutionary Solver | L2: A (Asymptote) | M2: B (distributable tasks) | N2: C (initiator contribution) | S2: Graph points to plot | U2: Negative | V2: Positive
E3: Negative | F3: Positive | H3: Negative | I3: Positive | L3: {=INDEX(DropDowns!M2:M10, MATCH(A2&B2, DropDowns!K2:K10&DropDowns!L2:L10, 0))} -> 1718.98 | M3: {=INDEX(DropDowns!N2:N10, MATCH(A2&B2, DropDowns!K2:K10&DropDowns!L2:L10, 0))} -> 9883.08 | N3: {=INDEX(DropDowns!O2:O10, MATCH(A2&B2, DropDowns!K2:K10&DropDowns!L2:L10, 0))} -> 1.11 | O3: Minimal bound (restricting overestimation) | P3: Maximal bound (restricting underestimation) | Q3: Evolutionary algorithm penalty for overestimation | S3: 0 | T3: =$L$3+($M$3/($S3+$N$3)) -> 10622.656 | U3: =$T$3-($D$4-$E$4) -> 645.65568 | V3: =($D$4+$F$4)-$T$3 -> 693.34432
B4: 0 Agents (Baseline) | C4: 0 | D4: =AVERAGEIFS(CoreParsedData[UBAVisualizer (Session) Time], CoreParsedData[Agents], $C$4, CoreParsedData[Cores/Agent], C4, CoreParsedData[Target], $A$2) -> 10630.75 | E4: =D4-_xlfn.MINIFS(CoreParsedData[UBAVisualizer (Session) Time], CoreParsedData[Agents], 0, CoreParsedData[Cores/Agent], C4, CoreParsedData[Target], $A$2) -> 653.75 | F4: =_xlfn.MAXIFS(CoreParsedData[UBAVisualizer (Session) Time], CoreParsedData[Agents], 0, CoreParsedData[Cores/Agent], C4, CoreParsedData[Target], $A$2)-D4 -> 685.25 | G4: 1 | H4: 0 | I4: 0 | K4: Agents | L4: Measured value | M4: Predicted Value | N4: Error^2 | S4: 1 | T4: =$L$3+($M$3/($S4+$N$3)) -> 6402.9042 | U4: =$T$4-($D$5-$E$5) -> 217.90417 | V4: =($D$5+$F$5)-$T$4 -> 435.09583
B5: 1 Agent | C5: 1 | D5: =IFERROR(AVERAGEIFS(CoreParsedData[UBAVisualizer (Session) Time], CoreParsedData[Agents], C5, CoreParsedData[Cores/Agent], $B$2, CoreParsedData[Target], $A$2), NA()) -> 6522 | E5: =D5-_xlfn.MINIFS(CoreParsedData[UBAVisualizer (Session) Time], CoreParsedData[Agents], C5, CoreParsedData[Cores/Agent], $B$2, CoreParsedData[Target], $A$2) -> 337 | F5: =_xlfn.MAXIFS(CoreParsedData[UBAVisualizer (Session) Time], CoreParsedData[Agents], C5, CoreParsedData[Cores/Agent], $B$2, CoreParsedData[Target], $A$2)-D5 -> 316 | G5: =$D$4/D5 -> 1.6299831 | H5: =($D$4/D5)-($D$4/(D5+F5)) -> 0.075325339 | I5: =($D$4/(D5-E5))-($D$4/D5) -> 0.088812339 | K5: 0 | L5: =D4 -> 10630.75 | M5: =$L$3+($M$3/(1*$K5+$N$3)) -> 10622.656 | N5: =_xlfn.IFNA((M5-L5)^2, 0) -> 65.518086 | O5: =_xlfn.IFNA(D4-E4, 0) -> 9977 | P5: =_xlfn.IFNA(D4+F4, 999999) -> 11316 | Q5: =IF(AND(NOT(ISNA(L5)), M5 < O5), (O5 - L5)^2*1000000, 0) -> 0 | S5: 2 | T5: =$L$3+($M$3/($S5+$N$3)) -> 4896.8192 | U5: 0 | V5: 0
B6: 4 Agents | C6: 4 | D6: =IFERROR(AVERAGEIFS(CoreParsedData[UBAVisualizer (Session) Time], CoreParsedData[Agents], C6, CoreParsedData[Cores/Agent], $B$2, CoreParsedData[Target], $A$2), NA()) -> 3368.25 | E6: =D6-_xlfn.MINIFS(CoreParsedData[UBAVisualizer (Session) Time], CoreParsedData[Agents], C6, CoreParsedData[Cores/Agent], $B$2, CoreParsedData[Target], $A$2) -> 82.25 | F6: =_xlfn.MAXIFS(CoreParsedData[UBAVisualizer (Session) Time], CoreParsedData[Agents], C6, CoreParsedData[Cores/Agent], $B$2, CoreParsedData[Target], $A$2)-D6 -> 193.75 | G6: =$D$4/D6 -> 3.1561642 | H6: =($D$4/D6)-($D$4/(D6+F6)) -> 0.17167513 | I6: =($D$4/(D6-E6))-($D$4/D6) -> 0.079000153 | K6: 1 | L6: =D5 -> 6522 | M6: =$L$3+($M$3/(1*$K6+$N$3)) -> 6402.9042 | N6: =_xlfn.IFNA((M6-L6)^2, 0) -> 14183.817 | O6: =_xlfn.IFNA(D5-E5, 0) -> 6185 | P6: =_xlfn.IFNA(D5+F5, 999999) -> 6838 | Q6: =IF(AND(NOT(ISNA(L6)), M6 < O6), (O6 - L6)^2*1000000, 0) -> 0 | S6: 3 | T6: =$L$3+($M$3/($S6+$N$3)) -> 4123.6223 | U6: 0 | V6: 0
B7: 8 Agents | C7: 8 | D7: =IFERROR(AVERAGEIFS(CoreParsedData[UBAVisualizer (Session) Time], CoreParsedData[Agents], C7, CoreParsedData[Cores/Agent], $B$2, CoreParsedData[Target], $A$2), NA()) -> 2999.25 | E7: =D7-_xlfn.MINIFS(CoreParsedData[UBAVisualizer (Session) Time], CoreParsedData[Agents], C7, CoreParsedData[Cores/Agent], $B$2, CoreParsedData[Target], $A$2) -> 298.25 | F7: =_xlfn.MAXIFS(CoreParsedData[UBAVisualizer (Session) Time], CoreParsedData[Agents], C7, CoreParsedData[Cores/Agent], $B$2, CoreParsedData[Target], $A$2)-D7 -> 265.75 | G7: =$D$4/D7 -> 3.5444695 | H7: =($D$4/D7)-($D$4/(D7+F7)) -> 0.28849702 | I7: =($D$4/(D7-E7))-($D$4/D7) -> 0.39138764 | K7: 4 | L7: =D6 -> 3368.25 | M7: =$L$3+($M$3/(1*$K7+$N$3)) -> 3653.0465 | N7: =_xlfn.IFNA((M7-L7)^2, 0) -> 81109.067 | O7: =_xlfn.IFNA(D6-E6, 0) -> 3286 | P7: =_xlfn.IFNA(D6+F6, 999999) -> 3562 | Q7: =IF(AND(NOT(ISNA(L7)), M7 < O7), (O7 - L7)^2*1000000, 0) -> 0 | S7: 4 | T7: =$L$3+($M$3/($S7+$N$3)) -> 3653.0465 | U7: =$T$7-($D$6-$E$6) -> 367.04654 | V7: =($D$6+$F$6)-$T$7 -> -91.046536
K8: 8 | L8: =D7 -> 2999.25 | M8: =$L$3+($M$3/(1*$K8+$N$3)) -> 2803.8406 | N8: =_xlfn.IFNA((M8-L8)^2, 0) -> 38184.836 | O8: =_xlfn.IFNA(D7-E7, 0) -> 2701 | P8: =_xlfn.IFNA(D7+F7, 999999) -> 3265 | Q8: =IF(AND(NOT(ISNA(L8)), M8 < O8), (O8 - L8)^2*1000000, 0) -> 0 | S8: 5 | T8: =$L$3+($M$3/($S8+$N$3)) -> 3336.5054 | U8: 0 | V8: 0
M9: Total Error^2: | N9: =SUM(N5:N8) -> 133543.24 | O9: Evolutionary Algorithm Target: | Q9: =N9 + SUM(Q5:Q8) -> 133543.24 | S9: 6 | T9: =$L$3+($M$3/($S9+$N$3)) -> 3109.0053 | U9: 0 | V9: 0
M10: RMSE: | N10: =SQRT(N9/COUNT(L5:L8)) -> 182.71784 | S10: 7 | T10: =$L$3+($M$3/($S10+$N$3)) -> 2937.6089 | U10: 0 | V10: 0
M11: Deviation from global mean: | N11: {=N10/AVERAGE(IF(ISNUMBER(D4:D11), D4:D11))} -> 0.031074133 | S11: 8 | T11: =$L$3+($M$3/($S11+$N$3)) -> 2803.8406 | U11: =$T$11-($D$7-$E$7) -> 102.84059 | V11: =($D$7+$F$7)-$T$11 -> 461.15941
M12: Parallelization Percentile: | N12: =(M3/N3)/(L3+(M3/N3)) -> 0.83817794 | S12: 9 | T12: =$L$3+($M$3/($S12+$N$3)) -> 2696.5349 | U12: 0 | V12: 0
M13: Max Theoretical speedup: | N13: =D4/L3 -> 6.1843361 | S13: 10 | T13: =$L$3+($M$3/($S13+$N$3)) -> 2608.5462 | U13: 0 | V13: 0
S14: 11 | T14: =$L$3+($M$3/($S14+$N$3)) -> 2535.089 | U14: 0 | V14: 0
S15: 12 | T15: =$L$3+($M$3/($S15+$N$3)) -> 2472.8381 | U15: 0 | V15: 0
S16: 13 | T16: =$L$3+($M$3/($S16+$N$3)) -> 2419.4109 | U16: 0 | V16: 0
S17: 14 | T17: =$L$3+($M$3/($S17+$N$3)) -> 2373.0554 | U17: 0 | V17: 0
S18: 15 | T18: =$L$3+($M$3/($S18+$N$3)) -> 2332.4549 | U18: 0 | V18: 0
S19: 16 | T19: =$L$3+($M$3/($S19+$N$3)) -> 2296.6001 | U19: 0 | V19: 0
S20: 17 | T20: =$L$3+($M$3/($S20+$N$3)) -> 2264.705 | U20: 0 | V20: 0
S21: 18 | T21: =$L$3+($M$3/($S21+$N$3)) -> 2236.148 | U21: 0 | V21: 0
S22: 19 | T22: =$L$3+($M$3/($S22+$N$3)) -> 2210.431 | U22: 0 | V22: 0
S23: 20 | T23: =$L$3+($M$3/($S23+$N$3)) -> 2187.1505 | U23: 0 | V23: 0
S24: 21 | T24: =$L$3+($M$3/($S24+$N$3)) -> 2165.9759 | U24: 0 | V24: 0
S25: 22 | T25: =$L$3+($M$3/($S25+$N$3)) -> 2146.6338 | U25: 0 | V25: 0
... S35: 32 | T35: =$L$3+($M$3/($S35+$N$3)) -> 2017.4723 | U35: 0 | V35: 0

Sheet Core Distribution Scaling
A1: Target: | B1: Number of Cores:
A2: UE5 | B2: 16 | C2: Agents | D2: Time | E2: Deviation | G2: Speedup | H2: Deviation
E3: Negative | F3: Positive | H3: Negative | I3: Positive
B4: 0 Agents (Baseline) | C4: 0 | D4: =AVERAGEIFS(CoreParsedData[UBAVisualizer (Session) Time], CoreParsedData[Agents], $C$4, CoreParsedData[Cores/Agent], C4, CoreParsedData[Target], $A$2) -> 10630.75 | E4: =D4-_xlfn.MINIFS(CoreParsedData[UBAVisualizer (Session) Time], CoreParsedData[Agents], 0, CoreParsedData[Cores/Agent], C4, CoreParsedData[Target], $A$2) -> 653.75 | F4: =_xlfn.MAXIFS(CoreParsedData[UBAVisualizer (Session) Time], CoreParsedData[Agents], 0, CoreParsedData[Cores/Agent], C4, CoreParsedData[Target], $A$2)-D4 -> 685.25 | G4: 1 | H4: 0 | I4: 0
B5: 1 Agent | C5: 1 | D5: =IFERROR(AVERAGEIFS(CoreParsedData[UBAVisualizer (Session) Time], CoreParsedData[Agents], C5, CoreParsedData[Total Cores], $B$2, CoreParsedData[Target], $A$2), NA()) -> 3076.25 | E5: =D5-_xlfn.MINIFS(CoreParsedData[UBAVisualizer (Session) Time], CoreParsedData[Agents], C5, CoreParsedData[Total Cores], $B$2, CoreParsedData[Target], $A$2) -> 58.25 | F5: =_xlfn.MAXIFS(CoreParsedData[UBAVisualizer (Session) Time], CoreParsedData[Agents], C5, CoreParsedData[Total Cores], $B$2, CoreParsedData[Target], $A$2)-D5 -> 56.75 | G5: =$D$4/D5 -> 3.4557497 | H5: =($D$4/D5)-($D$4/(D5+F5)) -> 0.062596168 | I5: =($D$4/(D5-E5))-($D$4/D5) -> 0.066698946
B6: 4 Agents | C6: 4 | D6: =IFERROR(AVERAGEIFS(CoreParsedData[UBAVisualizer (Session) Time], CoreParsedData[Agents], C6, CoreParsedData[Total Cores], $B$2, CoreParsedData[Target], $A$2), NA()) -> 3368.25 | E6: =D6-_xlfn.MINIFS(CoreParsedData[UBAVisualizer (Session) Time], CoreParsedData[Agents], C6, CoreParsedData[Total Cores], $B$2, CoreParsedData[Target], $A$2) -> 82.25 | F6: =_xlfn.MAXIFS(CoreParsedData[UBAVisualizer (Session) Time], CoreParsedData[Agents], C6, CoreParsedData[Total Cores], $B$2, CoreParsedData[Target], $A$2)-D6 -> 193.75 | G6: =$D$4/D6 -> 3.1561642 | H6: =($D$4/D6)-($D$4/(D6+F6)) -> 0.17167513 | I6: =($D$4/(D6-E6))-($D$4/D6) -> 0.079000153
B7: 8 Agents | C7: 8 | D7: =IFERROR(AVERAGEIFS(CoreParsedData[UBAVisualizer (Session) Time], CoreParsedData[Agents], C7, CoreParsedData[Total Cores], $B$2, CoreParsedData[Target], $A$2), NA()) -> #N/A | E7: =D7-_xlfn.MINIFS(CoreParsedData[UBAVisualizer (Session) Time], CoreParsedData[Agents], C7, CoreParsedData[Total Cores], $B$2, CoreParsedData[Target], $A$2) -> #N/A | F7: =_xlfn.MAXIFS(CoreParsedData[UBAVisualizer (Session) Time], CoreParsedData[Agents], C7, CoreParsedData[Total Cores], $B$2, CoreParsedData[Target], $A$2)-D7 -> #N/A | G7: =$D$4/D7 -> #N/A | H7: =($D$4/D7)-($D$4/(D7+F7)) -> #N/A | I7: =($D$4/(D7-E7))-($D$4/D7) -> #N/A

Sheet RAM Scaling
A1: Target:
A2: UnrealInsights | B2: RAM | C2: Time | D2: Deviation | F2: Baseline
D3: Negative | E3: Positive
A4: 1GB | B4: 1 | C4: =AVERAGEIFS(RAMParsedData[UBAVisualizer (Session) Time], RAMParsedData[RAM], B4, RAMParsedData[Target], $A$2) -> 583.5 | D4: =C4-_xlfn.MINIFS(RAMParsedData[UBAVisualizer (Session) Time], RAMParsedData[RAM], B4, RAMParsedData[Target], $A$2) -> 107.5 | E4: =_xlfn.MAXIFS(RAMParsedData[UBAVisualizer (Session) Time], RAMParsedData[RAM], B4, RAMParsedData[Target], $A$2)-C4 -> 61.5 | F4: =AVERAGEIFS(CoreParsedData[UBAVisualizer (Session) Time], CoreParsedData[Agents], 0, CoreParsedData[Cores/Agent], 0, CoreParsedData[Target], $A$2) -> 518.75
A5: 2GB | B5: 2 | C5: =AVERAGEIFS(RAMParsedData[UBAVisualizer (Session) Time], RAMParsedData[RAM], B5, RAMParsedData[Target], $A$2) -> 478.75 | D5: =C5-_xlfn.MINIFS(RAMParsedData[UBAVisualizer (Session) Time], RAMParsedData[RAM], B5, RAMParsedData[Target], $A$2) -> 49.75 | E5: =_xlfn.MAXIFS(RAMParsedData[UBAVisualizer (Session) Time], RAMParsedData[RAM], B5, RAMParsedData[Target], $A$2)-C5 -> 51.25 | F5: =AVERAGEIFS(CoreParsedData[UBAVisualizer (Session) Time], CoreParsedData[Agents], 0, CoreParsedData[Cores/Agent], 0, CoreParsedData[Target], $A$2) -> 518.75
A6: 4GB | B6: 4 | C6: =AVERAGEIFS(RAMParsedData[UBAVisualizer (Session) Time], RAMParsedData[RAM], B6, RAMParsedData[Target], $A$2) -> 172.25 | D6: =C6-_xlfn.MINIFS(RAMParsedData[UBAVisualizer (Session) Time], RAMParsedData[RAM], B6, RAMParsedData[Target], $A$2) -> 15.25 | E6: =_xlfn.MAXIFS(RAMParsedData[UBAVisualizer (Session) Time], RAMParsedData[RAM], B6, RAMParsedData[Target], $A$2)-C6 -> 12.75 | F6: =AVERAGEIFS(CoreParsedData[UBAVisualizer (Session) Time], CoreParsedData[Agents], 0, CoreParsedData[Cores/Agent], 0, CoreParsedData[Target], $A$2) -> 518.75
A7: 8GB | B7: 8 | C7: =AVERAGEIFS(RAMParsedData[UBAVisualizer (Session) Time], RAMParsedData[RAM], B7, RAMParsedData[Target], $A$2) -> 169.75 | D7: =C7-_xlfn.MINIFS(RAMParsedData[UBAVisualizer (Session) Time], RAMParsedData[RAM], B7, RAMParsedData[Target], $A$2) -> 15.75 | E7: =_xlfn.MAXIFS(RAMParsedData[UBAVisualizer (Session) Time], RAMParsedData[RAM], B7, RAMParsedData[Target], $A$2)-C7 -> 25.25 | F7: =AVERAGEIFS(CoreParsedData[UBAVisualizer (Session) Time], CoreParsedData[Agents], 0, CoreParsedData[Cores/Agent], 0, CoreParsedData[Target], $A$2) -> 518.75
A8: 16GB | B8: 16 | C8: =AVERAGEIFS(RAMParsedData[UBAVisualizer (Session) Time], RAMParsedData[RAM], B8, RAMParsedData[Target], $A$2) -> 191.25 | D8: =C8-_xlfn.MINIFS(RAMParsedData[UBAVisualizer (Session) Time], RAMParsedData[RAM], B8, RAMParsedData[Target], $A$2) -> 16.25 | E8: =_xlfn.MAXIFS(RAMParsedData[UBAVisualizer (Session) Time], RAMParsedData[RAM], B8, RAMParsedData[Target], $A$2)-C8 -> 16.75 | F8: =AVERAGEIFS(CoreParsedData[UBAVisualizer (Session) Time], CoreParsedData[Agents], 0, CoreParsedData[Cores/Agent], 0, CoreParsedData[Target], $A$2) -> 518.75
A9: 24GB | B9: 24 | C9: =AVERAGEIFS(RAMParsedData[UBAVisualizer (Session) Time], RAMParsedData[RAM], B9, RAMParsedData[Target], $A$2) -> 169 | D9: =C9-_xlfn.MINIFS(RAMParsedData[UBAVisualizer (Session) Time], RAMParsedData[RAM], B9, RAMParsedData[Target], $A$2) -> 29 | E9: =_xlfn.MAXIFS(RAMParsedData[UBAVisualizer (Session) Time], RAMParsedData[RAM], B9, RAMParsedData[Target], $A$2)-C9 -> 33 | F9: =AVERAGEIFS(CoreParsedData[UBAVisualizer (Session) Time], CoreParsedData[Agents], 0, CoreParsedData[Cores/Agent], 0, CoreParsedData[Target], $A$2) -> 518.75
B11: For some reason Excel doesn't dynamically recalculate the scale of these combo charts, resulting in barely visible bars. To solve this, these graphs are included without dynamic updating

Sheet DropDowns
A1: Target | B1: Agents | C1: Cores | D1: Dist. Cores | E1: Target | F1: Agents | G1: A | H1: B | I1: C | J1: error^2 | K1: Target | L1: Cores | M1: A | N1: B | O1: C | P1: error^2
A2: UE5 | B2: 1 | C2: 4 | D2: 16 | E2: UE5 | F2: 1 | G2: 795.58 | H2: 51979.92 | I2: 5.27 | J2: 96426.55 | K2: UE5 | L2: 4 | M2: 1718.98 | N2: 9883.08 | O2: 1.11 | P2: 132681.37
A3: UnrealInsights | B3: 4 | C3: 8 | D3: 32 | E3: UE5 | F3: 4 | G3: 1020.93 | H3: 49101.17 | I3: 5.11 | J3: 4379.31 | K3: UE5 | L3: 8 | M3: 1205.23 | N3: 5607.22 | O3: 0.59 | P3: 28921.66
A4: UnrealPackageTool | B4: 8 | C4: 12 | D4: 64 | E4: UE5 | F4: 8 | G4: 843.55 | H4: 87123.04 | I4: 8.88 | J4: 10435.41 | K4: UE5 | L4: 16 | M4: 1223.55 | N4: 2307.06 | O4: 0.25 | P4: 0
C5: 16 | D5: 96 | E5: UnrealInsights | F5: 1 | G5: 106.71 | H5: 1998.83 | I5: 4.85 | J5: 30.07 | K5: UE5 | L5: 12 | M5: Need More | N5: Than 2 | O5: Data Points
C6: 24 | E6: UnrealInsights | F6: 4 | G6: 106.27 | H6: 3100.14 | I6: 7.52 | J6: 59.79 | K6: UE5 | L6: 24 | M6: Need More | N6: Than 2 | O6: Data Points
C7: 32 | E7: UnrealInsights | F7: 8 | G7: 55.68 | H7: 9837.84 | I7: 21.2 | J7: 308.61 | K7: UE5 | L7: 32 | M7: Need More | N7: Than 2 | O7: Data Points
C8: 64 | E8: UnrealPackageTool | F8: 1 | G8: 78.72 | H8: 462.45 | I8: 5.17 | J8: 127.2 | K8: UE5 | L8: 64 | M8: Need More | N8: Than 2 | O8: Data Points
E9: UnrealPackageTool | F9: 4 | G9: 73.54 | H9: 537.37 | I9: 5.7 | J9: 41.34 | K9: UnrealInsights | L9: 4 | M9: 210.8 | N9: 191.24 | O9: 0.62 | P9: 497.93
E10: UnrealPackageTool | F10: 8 | G10: 68.63 | H10: 2256.56 | I10: 22.72 | J10: 45.06 | K10: UnrealInsights | L10: 8 | M10: 143.33 | N10: 173.96 | O10: 0.46 | P10: 132.25
K11: UnrealInsights | L11: 16 | M11: 123.08 | N11: 104.11 | O11: 0.26 | P11: 0
K12: UnrealInsights | L12: 12 | M12: Need More | N12: Than 2 | O12: Data Points
K13: UnrealInsights | L13: 24 | M13: Need More | N13: Than 2 | O13: Data Points
K14: UnrealInsights | L14: 32 | M14: Need More | N14: Than 2 | O14: Data Points
K15: UnrealInsights | L15: 64 | M15: Need More | N15: Than 2 | O15: Data Points
K16: UnrealPackageTool | L16: 4 | M16: 100.4 | N16: 43.77 | O16: 0.65 | P16: 126.98
K17: UnrealPackageTool | L17: 8 | M17: 79.09 | N17: 59.91 | O17: 0.67 | P17: 96.87
K18: UnrealPackageTool | L18: 16 | M18: 72.3 | N18: 34.71 | O18: 0.36 | P18: 0
K19: UnrealPackageTool | L19: 12 | M19: Need More | N19: Than 2 | O19: Data Points
K20: UnrealPackageTool | L20: 24 | M20: Need More | N20: Than 2 | O20: Data Points
K21: UnrealPackageTool | L21: 32 | M21: Need More | N21: Than 2 | O21: Data Points
K22: UnrealPackageTool | L22: 64 | M22: Need More | N22: Than 2 | O22: Data Points
